<?xml version="1.0" ?>
<sdf version="1.6">
  <model name="force_box">
    <pose>0 0 0.05 0 0 0</pose>
    <static>false</static>

    <!-- Base fija del sensor -->
    <link name="base_link">
      <inertial>
        <mass>0.001</mass>
        <inertia>
          <ixx>1e-6</ixx>
          <iyy>1e-6</iyy>
          <izz>1e-6</izz>
          <ixy>0.0</ixy>
          <ixz>0.0</ixz>
          <iyz>0.0</iyz>
        </inertia>
      </inertial>
    </link>

    <!-- Cuerpo medido del sensor -->
    <link name="sensor_link">
      <pose>0 0 0 0 0 0</pose>
      <gravity>false</gravity>

      <inertial>
        <mass>0.001</mass>
        <inertia>
          <ixx>1e-6</ixx>
          <iyy>1e-6</iyy>
          <izz>1e-6</izz>
          <ixy>0.0</ixy>
          <ixz>0.0</ixz>
          <iyz>0.0</iyz>
        </inertia>
      </inertial>

      <visual name="visual">
        <geometry>
          <mesh>
            <uri>model://force_box/meshes/FMAMSDXX015WC2C3.dae</uri>
            <scale>1 1 1</scale>
          </mesh>
        </geometry>
      </visual>

      <collision name="collision">
        <geometry>
          <box><size>0.00483 0.00483 0.00253</size></box>
        </geometry>
      </collision>
    </link>

    <!-- Unión fija entre base y sensor -->
    <joint name="force_joint" type="revolute">
      <parent>base_link</parent>
      <child>sensor_link</child>
    </joint>

    <!-- Sensor de fuerza (activar para pruebas reales con plugin) -->
    <!--
    <joint name="sensor_joint" type="fixed">
      <parent>base_link</parent>
      <child>sensor_link</child>

      <sensor name="force_sensor" type="force_torque">
        <always_on>true</always_on>
        <update_rate>100</update_rate>
        <plugin name="force_plugin" filename="libforce_plugin.so">
          <pose>0.00154 0.00234 0.00252 0 0 0</pose>
          <noise_stddev>0.03</noise_stddev>
          <min_lin_force>3</min_lin_force>
          <max_lin_force>12</max_lin_force>
          <min_force>0</min_force>
          <max_force>15</max_force>
          <resolution>0.0037</resolution>
        </plugin>
      </sensor>
    </joint>
    -->
  </model>
</sdf>
